Workbook

Sheet READ ME
A1: SORB-15 — the data behind the backtest result
A3: What is in this file
A4: Calculator — change 3 blue cells (taker fee, slippage, funding) and see the net P&L of the same 301 trades recalculate. Also shows the fee at which the rules would break even.
A5: Summary — the result split by sub-agent, session, side, exit reason and month. Live: it follows the Calculator.
A6: Trades — all 301 trades, times in IST, with the cost of each one broken into slippage, fees and funding.
A7: Settings — every value the backtest used, and who it came from: your rule, a value I chose, or an assumption to verify.
A8: Signals — every session the engine looked at (including the 278 where nothing qualified).
A9: Sensitivity — the 9 exact re-runs of the engine from the notebook (these are exact; the Calculator is a recompute).
A11: Two things you should know before you check it
A12: 1. 'Gross' in my notebook already has slippage taken out of it. The engine applies slippage to every fill price, so it never appears under 'costs'. The notebook label ('gross is price movement only') was wrong. This file separates the three: gross before slippage, slippage, fees (+ funding). The NET figure was never affected.
A13: 2. The Calculator re-prices the same 301 trades. If you change costs in the real engine, the daily-loss limit and the 4-loss halt can change WHICH trades happen (my own 0.04% fee test ran 304 trades, not 301). For the exact answer, put your values in the OV line of the notebook (cell 2) and run all. For checking whether the conclusion survives a different fee or slippage, the Calculator is accurate to within a few rupees (at the values I used it reproduces the backtest net to within Rs 1).
A15: The candle data
... A20: Colour code: blue text on yellow = a value you can change. Black = formula.

Sheet Calculator
A1: Change the three blue/yellow cells. Net P&L of the same 301 trades recalculates.
A2: Costs are charged per side (entry and each exit). Slippage is applied to every fill. 'As run' = the values my backtest used.
A4: Input | B4: YOUR value | C4: Used in my backtest | D4: Note
A5: Taker fee (per side) | B5: 0.00059 | C5: 0.00059 | D5: ASSUMED by me — never confirmed against your CoinDCX account (0.059% = 0.05% + 18% GST).
A6: Slippage (per side) | B6: 0.0002 | C6: 0.0002 | D6: ASSUMED by me. Applied to entry and every exit fill.
A7: Funding rate per 8 hours | B7: 0.0001 | C7: 0.0001 | D7: ASSUMED (typical BTC perpetual). Charged on hold time; tiny at these hold times.
A9: Result (₹) | B9: With YOUR values | C9: As run (my backtest) | D9: Difference
A10: Trades | B10: =COUNT(Trades!W2:W302) -> 301 | C10: =COUNT(Trades!P2:P302) -> 301 | D10: =B10-C10 -> 0
A11: Gross P&L before slippage | B11: =SUM(Trades!S2:S302) -> 3265.5287 | C11: =SUM(Trades!S2:S302) -> 3265.5287 | D11: =B11-C11 -> 0
A12: Slippage | B12: =SUM(Trades!T2:T302)-SUM(Trades!S2:S302) -> -2026.1378 | C12: =SUM(Trades!O2:O302)-SUM(Trades!S2:S302) -> -2026.1378 | D12: =B12-C12 -> 0
A13: Fees | B13: =-SUM(Trades!U2:U302) -> -5977.1066 | C13: =-SUM(Trades!Q2:Q302) -> -5977.1066 | D13: =B13-C13 -> 0
A14: Funding | B14: =-SUM(Trades!V2:V302) -> -67.236661 | C14: =-SUM(Trades!R2:R302) -> -67.236661 | D14: =B14-C14 -> 0
A15: NET P&L | B15: =SUM(Trades!W2:W302) -> -4804.9524 | C15: =SUM(Trades!P2:P302) -> -4804.9524 | D15: =B15-C15 -> 0
A16: Net per trade | B16: =B15/B10 -> -15.963297 | C16: =C15/C10 -> -15.963297 | D16: =B16-C16 -> 0
A17: Return on capital | B17: =B15/Settings!$B$2 -> -0.96099049 | C17: =C15/Settings!$B$2 -> -0.96099049 | D17: =B17-C17 -> 0
A18: Win rate (net > 0) | B18: =COUNTIF(Trades!W2:W302,">0")/B10 -> 0.61461794 | C18: =COUNTIF(Trades!P2:P302,">0")/C10 -> 0.61461794 | D18: =B18-C18 -> 0
A19: Profit factor | B19: =SUMIF(Trades!W2:W302,">0")/-SUMIF(Trades!W2:W302,"<0") -> 0.53346769 | C19: =SUMIF(Trades!P2:P302,">0")/-SUMIF(Trades!P2:P302,"<0") -> 0.53346769 | D19: =B19-C19 -> 0
A20: Ending balance (start = capital) | B20: =Settings!$B$2+B15 -> 195.04757 | C20: =Settings!$B$2+C15 -> 195.04757 | D20: =B20-C20 -> 0
A22: Where would it break even?
A23: Taker fee at which NET = 0 (with your slippage and funding) | B23: =(SUM(Trades!T2:T302)-SUM(Trades!V2:V302))/(2*SUM(Trades!M2:M302)) -> 0.0001157033
A24: Slippage at which NET = 0 (with your fee and funding) | B24: =(SUM(Trades!S2:S302)-2*B5*SUM(Trades!M2:M302)-SUM(Trades!V2:V302))/(2*SUM(Trades!M2:M302)) -> -0.0002742967
A25: NET with ZERO fee and ZERO slippage (funding kept) | B25: =SUM(Trades!S2:S302)-SUM(Trades!V2:V302) -> 3198.292
A27: NET ₹ for any combination (your funding rate). Edit the blue fee / slippage headers.
A28: Taker fee ↓ / Slippage → | B28: 0.0002 | C28: 0.0001 | D28: 5e-05 | E28: 0
A29: 0.00059 | B29: =SUM(Trades!$S$2:$S$302)-2*B$28*SUM(Trades!$M$2:$M$302)-2*$A29*SUM(Trades!$M$2:$M$302)-SUM(Trades!$V$2:$V$302) -> -4804.9524 | C29: =SUM(Trades!$S$2:$S$302)-2*C$28*SUM(Trades!$M$2:$M$302)-2*$A29*SUM(Trades!$M$2:$M$302)-SUM(Trades!$V$2:$V$302) -> -3791.8835 | D29: =SUM(Trades!$S$2:$S$302)-2*D$28*SUM(Trades!$M$2:$M$302)-2*$A29*SUM(Trades!$M$2:$M$302)-SUM(Trades!$V$2:$V$302) -> -3285.3491 | E29: =SUM(Trades!$S$2:$S$302)-2*E$28*SUM(Trades!$M$2:$M$302)-2*$A29*SUM(Trades!$M$2:$M$302)-SUM(Trades!$V$2:$V$302) -> -2778.8146
A30: 0.0005 | B30: =SUM(Trades!$S$2:$S$302)-2*B$28*SUM(Trades!$M$2:$M$302)-2*$A30*SUM(Trades!$M$2:$M$302)-SUM(Trades!$V$2:$V$302) -> -3893.1904 | C30: =SUM(Trades!$S$2:$S$302)-2*C$28*SUM(Trades!$M$2:$M$302)-2*$A30*SUM(Trades!$M$2:$M$302)-SUM(Trades!$V$2:$V$302) -> -2880.1215 | D30: =SUM(Trades!$S$2:$S$302)-2*D$28*SUM(Trades!$M$2:$M$302)-2*$A30*SUM(Trades!$M$2:$M$302)-SUM(Trades!$V$2:$V$302) -> -2373.587 | E30: =SUM(Trades!$S$2:$S$302)-2*E$28*SUM(Trades!$M$2:$M$302)-2*$A30*SUM(Trades!$M$2:$M$302)-SUM(Trades!$V$2:$V$302) -> -1867.0526
A31: 0.0004 | B31: =SUM(Trades!$S$2:$S$302)-2*B$28*SUM(Trades!$M$2:$M$302)-2*$A31*SUM(Trades!$M$2:$M$302)-SUM(Trades!$V$2:$V$302) -> -2880.1215 | C31: =SUM(Trades!$S$2:$S$302)-2*C$28*SUM(Trades!$M$2:$M$302)-2*$A31*SUM(Trades!$M$2:$M$302)-SUM(Trades!$V$2:$V$302) -> -1867.0526 | D31: =SUM(Trades!$S$2:$S$302)-2*D$28*SUM(Trades!$M$2:$M$302)-2*$A31*SUM(Trades!$M$2:$M$302)-SUM(Trades!$V$2:$V$302) -> -1360.5181 | E31: =SUM(Trades!$S$2:$S$302)-2*E$28*SUM(Trades!$M$2:$M$302)-2*$A31*SUM(Trades!$M$2:$M$302)-SUM(Trades!$V$2:$V$302) -> -853.98366
A32: 0.0003 | B32: =SUM(Trades!$S$2:$S$302)-2*B$28*SUM(Trades!$M$2:$M$302)-2*$A32*SUM(Trades!$M$2:$M$302)-SUM(Trades!$V$2:$V$302) -> -1867.0526 | C32: =SUM(Trades!$S$2:$S$302)-2*C$28*SUM(Trades!$M$2:$M$302)-2*$A32*SUM(Trades!$M$2:$M$302)-SUM(Trades!$V$2:$V$302) -> -853.98366 | D32: =SUM(Trades!$S$2:$S$302)-2*D$28*SUM(Trades!$M$2:$M$302)-2*$A32*SUM(Trades!$M$2:$M$302)-SUM(Trades!$V$2:$V$302) -> -347.44921 | E32: =SUM(Trades!$S$2:$S$302)-2*E$28*SUM(Trades!$M$2:$M$302)-2*$A32*SUM(Trades!$M$2:$M$302)-SUM(Trades!$V$2:$V$302) -> 159.08525
A33: 0.0002 | B33: =SUM(Trades!$S$2:$S$302)-2*B$28*SUM(Trades!$M$2:$M$302)-2*$A33*SUM(Trades!$M$2:$M$302)-SUM(Trades!$V$2:$V$302) -> -853.98366 | C33: =SUM(Trades!$S$2:$S$302)-2*C$28*SUM(Trades!$M$2:$M$302)-2*$A33*SUM(Trades!$M$2:$M$302)-SUM(Trades!$V$2:$V$302) -> 159.08525 | D33: =SUM(Trades!$S$2:$S$302)-2*D$28*SUM(Trades!$M$2:$M$302)-2*$A33*SUM(Trades!$M$2:$M$302)-SUM(Trades!$V$2:$V$302) -> 665.61971 | E33: =SUM(Trades!$S$2:$S$302)-2*E$28*SUM(Trades!$M$2:$M$302)-2*$A33*SUM(Trades!$M$2:$M$302)-SUM(Trades!$V$2:$V$302) -> 1172.1542
A34: 0.0001 | B34: =SUM(Trades!$S$2:$S$302)-2*B$28*SUM(Trades!$M$2:$M$302)-2*$A34*SUM(Trades!$M$2:$M$302)-SUM(Trades!$V$2:$V$302) -> 159.08525 | C34: =SUM(Trades!$S$2:$S$302)-2*C$28*SUM(Trades!$M$2:$M$302)-2*$A34*SUM(Trades!$M$2:$M$302)-SUM(Trades!$V$2:$V$302) -> 1172.1542 | D34: =SUM(Trades!$S$2:$S$302)-2*D$28*SUM(Trades!$M$2:$M$302)-2*$A34*SUM(Trades!$M$2:$M$302)-SUM(Trades!$V$2:$V$302) -> 1678.6886 | E34: =SUM(Trades!$S$2:$S$302)-2*E$28*SUM(Trades!$M$2:$M$302)-2*$A34*SUM(Trades!$M$2:$M$302)-SUM(Trades!$V$2:$V$302) -> 2185.2231
A35: 0 | B35: =SUM(Trades!$S$2:$S$302)-2*B$28*SUM(Trades!$M$2:$M$302)-2*$A35*SUM(Trades!$M$2:$M$302)-SUM(Trades!$V$2:$V$302) -> 1172.1542 | C35: =SUM(Trades!$S$2:$S$302)-2*C$28*SUM(Trades!$M$2:$M$302)-2*$A35*SUM(Trades!$M$2:$M$302)-SUM(Trades!$V$2:$V$302) -> 2185.2231 | D35: =SUM(Trades!$S$2:$S$302)-2*D$28*SUM(Trades!$M$2:$M$302)-2*$A35*SUM(Trades!$M$2:$M$302)-SUM(Trades!$V$2:$V$302) -> 2691.7575 | E35: =SUM(Trades!$S$2:$S$302)-2*E$28*SUM(Trades!$M$2:$M$302)-2*$A35*SUM(Trades!$M$2:$M$302)-SUM(Trades!$V$2:$V$302) -> 3198.292
A37: How to read it: green = the 301 trades would have made money under that fee and slippage; red = they would have lost.
A38: This re-prices the same trades. The real engine can also change which trades happen when costs change (daily-loss limit, 4-loss halt) — use OV in the notebook for the exact figure.
A39: Funding is derived per trade from my backtest (gross - net - fees). It is small: it is the only figure I could not take straight from the trade file.

Sheet Summary
A1: Result by group — follows the Calculator (column F uses YOUR fee / slippage / funding)
A3: Group | B3: Trades | C3: Gross before slippage ₹ | D3: NET ₹ as run | E3: NET ₹ with YOUR values | F3: Win rate (YOUR values)
A4: SUB-AGENT
A5: SA1 | B5: =COUNTIFS(Trades!$D$2:$D$302,$A5) -> 75 | C5: =SUMIFS(Trades!$S$2:$S$302,Trades!$D$2:$D$302,$A5) -> 1602.6552 | D5: =SUMIFS(Trades!$P$2:$P$302,Trades!$D$2:$D$302,$A5) -> -1317.6669 | E5: =SUMIFS(Trades!$W$2:$W$302,Trades!$D$2:$D$302,$A5) -> -1317.6669 | F5: =IF(B5=0,0,COUNTIFS(Trades!$D$2:$D$302,$A5,Trades!$W$2:$W$302,">0")/B5) -> 0.56
A6: SA2 | B6: =COUNTIFS(Trades!$D$2:$D$302,$A6) -> 220 | C6: =SUMIFS(Trades!$S$2:$S$302,Trades!$D$2:$D$302,$A6) -> 1711.1269 | D6: =SUMIFS(Trades!$P$2:$P$302,Trades!$D$2:$D$302,$A6) -> -3144.0597 | E6: =SUMIFS(Trades!$W$2:$W$302,Trades!$D$2:$D$302,$A6) -> -3144.0597 | F6: =IF(B6=0,0,COUNTIFS(Trades!$D$2:$D$302,$A6,Trades!$W$2:$W$302,">0")/B6) -> 0.64545455
A7: SA4 | B7: =COUNTIFS(Trades!$D$2:$D$302,$A7) -> 6 | C7: =SUMIFS(Trades!$S$2:$S$302,Trades!$D$2:$D$302,$A7) -> -48.253437 | D7: =SUMIFS(Trades!$P$2:$P$302,Trades!$D$2:$D$302,$A7) -> -343.2258 | E7: =SUMIFS(Trades!$W$2:$W$302,Trades!$D$2:$D$302,$A7) -> -343.2258 | F7: =IF(B7=0,0,COUNTIFS(Trades!$D$2:$D$302,$A7,Trades!$W$2:$W$302,">0")/B7) -> 0.16666667
A9: SESSION
A10: London | B10: =COUNTIFS(Trades!$C$2:$C$302,$A10) -> 162 | C10: =SUMIFS(Trades!$S$2:$S$302,Trades!$C$2:$C$302,$A10) -> 1850.8064 | D10: =SUMIFS(Trades!$P$2:$P$302,Trades!$C$2:$C$302,$A10) -> -2939.2401 | E10: =SUMIFS(Trades!$W$2:$W$302,Trades!$C$2:$C$302,$A10) -> -2939.2401 | F10: =IF(B10=0,0,COUNTIFS(Trades!$C$2:$C$302,$A10,Trades!$W$2:$W$302,">0")/B10) -> 0.58641975
A11: New York | B11: =COUNTIFS(Trades!$C$2:$C$302,$A11) -> 139 | C11: =SUMIFS(Trades!$S$2:$S$302,Trades!$C$2:$C$302,$A11) -> 1414.7223 | D11: =SUMIFS(Trades!$P$2:$P$302,Trades!$C$2:$C$302,$A11) -> -1865.7123 | E11: =SUMIFS(Trades!$W$2:$W$302,Trades!$C$2:$C$302,$A11) -> -1865.7123 | F11: =IF(B11=0,0,COUNTIFS(Trades!$C$2:$C$302,$A11,Trades!$W$2:$W$302,">0")/B11) -> 0.64748201
A13: SIDE
A14: LONG | B14: =COUNTIFS(Trades!$E$2:$E$302,$A14) -> 140 | C14: =SUMIFS(Trades!$S$2:$S$302,Trades!$E$2:$E$302,$A14) -> 1807.1158 | D14: =SUMIFS(Trades!$P$2:$P$302,Trades!$E$2:$E$302,$A14) -> -2014.7058 | E14: =SUMIFS(Trades!$W$2:$W$302,Trades!$E$2:$E$302,$A14) -> -2014.7058 | F14: =IF(B14=0,0,COUNTIFS(Trades!$E$2:$E$302,$A14,Trades!$W$2:$W$302,">0")/B14) -> 0.65
A15: SHORT | B15: =COUNTIFS(Trades!$E$2:$E$302,$A15) -> 161 | C15: =SUMIFS(Trades!$S$2:$S$302,Trades!$E$2:$E$302,$A15) -> 1458.4129 | D15: =SUMIFS(Trades!$P$2:$P$302,Trades!$E$2:$E$302,$A15) -> -2790.2466 | E15: =SUMIFS(Trades!$W$2:$W$302,Trades!$E$2:$E$302,$A15) -> -2790.2466 | F15: =IF(B15=0,0,COUNTIFS(Trades!$E$2:$E$302,$A15,Trades!$W$2:$W$302,">0")/B15) -> 0.58385093
A17: EXIT REASON
A18: trailing_stop | B18: =COUNTIFS(Trades!$K$2:$K$302,$A18) -> 189 | C18: =SUMIFS(Trades!$S$2:$S$302,Trades!$K$2:$K$302,$A18) -> 10373.618 | D18: =SUMIFS(Trades!$P$2:$P$302,Trades!$K$2:$K$302,$A18) -> 5425.462 | E18: =SUMIFS(Trades!$W$2:$W$302,Trades!$K$2:$K$302,$A18) -> 5425.462 | F18: =IF(B18=0,0,COUNTIFS(Trades!$K$2:$K$302,$A18,Trades!$W$2:$W$302,">0")/B18) -> 0.96296296
A19: stop_loss | B19: =COUNTIFS(Trades!$K$2:$K$302,$A19) -> 89 | C19: =SUMIFS(Trades!$S$2:$S$302,Trades!$K$2:$K$302,$A19) -> -7013.7332 | D19: =SUMIFS(Trades!$P$2:$P$302,Trades!$K$2:$K$302,$A19) -> -9471.5629 | E19: =SUMIFS(Trades!$W$2:$W$302,Trades!$K$2:$K$302,$A19) -> -9471.5629 | F19: =IF(B19=0,0,COUNTIFS(Trades!$K$2:$K$302,$A19,Trades!$W$2:$W$302,">0")/B19) -> 0
A20: session_end | B20: =COUNTIFS(Trades!$K$2:$K$302,$A20) -> 21 | C20: =SUMIFS(Trades!$S$2:$S$302,Trades!$K$2:$K$302,$A20) -> -229.84704 | D20: =SUMIFS(Trades!$P$2:$P$302,Trades!$K$2:$K$302,$A20) -> -738.0694 | E20: =SUMIFS(Trades!$W$2:$W$302,Trades!$K$2:$K$302,$A20) -> -738.0694 | F20: =IF(B20=0,0,COUNTIFS(Trades!$K$2:$K$302,$A20,Trades!$W$2:$W$302,">0")/B20) -> 0.14285714
A21: breakeven_stop | B21: =COUNTIFS(Trades!$K$2:$K$302,$A21) -> 2 | C21: =SUMIFS(Trades!$S$2:$S$302,Trades!$K$2:$K$302,$A21) -> 135.49102 | D21: =SUMIFS(Trades!$P$2:$P$302,Trades!$K$2:$K$302,$A21) -> -20.782092 | E21: =SUMIFS(Trades!$W$2:$W$302,Trades!$K$2:$K$302,$A21) -> -20.782092 | F21: =IF(B21=0,0,COUNTIFS(Trades!$K$2:$K$302,$A21,Trades!$W$2:$W$302,">0")/B21) -> 0
A23: MONTH
A24: 2025-12 | B24: =COUNTIFS(Trades!$X$2:$X$302,$A24) -> 1 | C24: =SUMIFS(Trades!$S$2:$S$302,Trades!$X$2:$X$302,$A24) -> 43.534766 | D24: =SUMIFS(Trades!$P$2:$P$302,Trades!$X$2:$X$302,$A24) -> 6.4227275 | E24: =SUMIFS(Trades!$W$2:$W$302,Trades!$X$2:$X$302,$A24) -> 6.4227275 | F24: =IF(B24=0,0,COUNTIFS(Trades!$X$2:$X$302,$A24,Trades!$W$2:$W$302,">0")/B24) -> 1
A25: 2026-01 | B25: =COUNTIFS(Trades!$X$2:$X$302,$A25) -> 32 | C25: =SUMIFS(Trades!$S$2:$S$302,Trades!$X$2:$X$302,$A25) -> 541.76607 | D25: =SUMIFS(Trades!$P$2:$P$302,Trades!$X$2:$X$302,$A25) -> -529.29121 | E25: =SUMIFS(Trades!$W$2:$W$302,Trades!$X$2:$X$302,$A25) -> -529.29121 | F25: =IF(B25=0,0,COUNTIFS(Trades!$X$2:$X$302,$A25,Trades!$W$2:$W$302,">0")/B25) -> 0.5625
A26: 2026-02 | B26: =COUNTIFS(Trades!$X$2:$X$302,$A26) -> 28 | C26: =SUMIFS(Trades!$S$2:$S$302,Trades!$X$2:$X$302,$A26) -> -709.26229 | D26: =SUMIFS(Trades!$P$2:$P$302,Trades!$X$2:$X$302,$A26) -> -1273.8842 | E26: =SUMIFS(Trades!$W$2:$W$302,Trades!$X$2:$X$302,$A26) -> -1273.8842 | F26: =IF(B26=0,0,COUNTIFS(Trades!$X$2:$X$302,$A26,Trades!$W$2:$W$302,">0")/B26) -> 0.42857143
A27: 2026-03 | B27: =COUNTIFS(Trades!$X$2:$X$302,$A27) -> 30 | C27: =SUMIFS(Trades!$S$2:$S$302,Trades!$X$2:$X$302,$A27) -> 759.11072 | D27: =SUMIFS(Trades!$P$2:$P$302,Trades!$X$2:$X$302,$A27) -> 12.327883 | E27: =SUMIFS(Trades!$W$2:$W$302,Trades!$X$2:$X$302,$A27) -> 12.327883 | F27: =IF(B27=0,0,COUNTIFS(Trades!$X$2:$X$302,$A27,Trades!$W$2:$W$302,">0")/B27) -> 0.8
A28: 2026-04 | B28: =COUNTIFS(Trades!$X$2:$X$302,$A28) -> 34 | C28: =SUMIFS(Trades!$S$2:$S$302,Trades!$X$2:$X$302,$A28) -> 219.8379 | D28: =SUMIFS(Trades!$P$2:$P$302,Trades!$X$2:$X$302,$A28) -> -599.92808 | E28: =SUMIFS(Trades!$W$2:$W$302,Trades!$X$2:$X$302,$A28) -> -599.92808 | F28: =IF(B28=0,0,COUNTIFS(Trades!$X$2:$X$302,$A28,Trades!$W$2:$W$302,">0")/B28) -> 0.64705882
A29: 2026-05 | B29: =COUNTIFS(Trades!$X$2:$X$302,$A29) -> 30 | C29: =SUMIFS(Trades!$S$2:$S$302,Trades!$X$2:$X$302,$A29) -> 812.85749 | D29: =SUMIFS(Trades!$P$2:$P$302,Trades!$X$2:$X$302,$A29) -> 21.41465 | E29: =SUMIFS(Trades!$W$2:$W$302,Trades!$X$2:$X$302,$A29) -> 21.41465 | F29: =IF(B29=0,0,COUNTIFS(Trades!$X$2:$X$302,$A29,Trades!$W$2:$W$302,">0")/B29) -> 0.73333333
A30: 2026-06 | B30: =COUNTIFS(Trades!$X$2:$X$302,$A30) -> 32 | C30: =SUMIFS(Trades!$S$2:$S$302,Trades!$X$2:$X$302,$A30) -> 298.58225 | D30: =SUMIFS(Trades!$P$2:$P$302,Trades!$X$2:$X$302,$A30) -> -462.59296 | E30: =SUMIFS(Trades!$W$2:$W$302,Trades!$X$2:$X$302,$A30) -> -462.59296 | F30: =IF(B30=0,0,COUNTIFS(Trades!$X$2:$X$302,$A30,Trades!$W$2:$W$302,">0")/B30) -> 0.6875
A31: 2026-07 | B31: =COUNTIFS(Trades!$X$2:$X$302,$A31) -> 36 | C31: =SUMIFS(Trades!$S$2:$S$302,Trades!$X$2:$X$302,$A31) -> 481.3533 | D31: =SUMIFS(Trades!$P$2:$P$302,Trades!$X$2:$X$302,$A31) -> -526.0335 | E31: =SUMIFS(Trades!$W$2:$W$302,Trades!$X$2:$X$302,$A31) -> -526.0335 | F31: =IF(B31=0,0,COUNTIFS(Trades!$X$2:$X$302,$A31,Trades!$W$2:$W$302,">0")/B31) -> 0.63888889
A32: 2026-08 | B32: =COUNTIFS(Trades!$X$2:$X$302,$A32) -> 34 | C32: =SUMIFS(Trades!$S$2:$S$302,Trades!$X$2:$X$302,$A32) -> 526.88702 | D32: =SUMIFS(Trades!$P$2:$P$302,Trades!$X$2:$X$302,$A32) -> -543.97172 | E32: =SUMIFS(Trades!$W$2:$W$302,Trades!$X$2:$X$302,$A32) -> -543.97172 | F32: =IF(B32=0,0,COUNTIFS(Trades!$X$2:$X$302,$A32,Trades!$W$2:$W$302,">0")/B32) -> 0.47058824
A33: 2026-09 | B33: =COUNTIFS(Trades!$X$2:$X$302,$A33) -> 29 | C33: =SUMIFS(Trades!$S$2:$S$302,Trades!$X$2:$X$302,$A33) -> 112.60704 | D33: =SUMIFS(Trades!$P$2:$P$302,Trades!$X$2:$X$302,$A33) -> -628.34132 | E33: =SUMIFS(Trades!$W$2:$W$302,Trades!$X$2:$X$302,$A33) -> -628.34132 | F33: =IF(B33=0,0,COUNTIFS(Trades!$X$2:$X$302,$A33,Trades!$W$2:$W$302,">0")/B33) -> 0.55172414
A34: 2026-10 | B34: =COUNTIFS(Trades!$X$2:$X$302,$A34) -> 15 | C34: =SUMIFS(Trades!$S$2:$S$302,Trades!$X$2:$X$302,$A34) -> 178.2544 | D34: =SUMIFS(Trades!$P$2:$P$302,Trades!$X$2:$X$302,$A34) -> -281.0747 | E34: =SUMIFS(Trades!$W$2:$W$302,Trades!$X$2:$X$302,$A34) -> -281.0747 | F34: =IF(B34=0,0,COUNTIFS(Trades!$X$2:$X$302,$A34,Trades!$W$2:$W$302,">0")/B34) -> 0.6

Sheet Settings
A1: Setting | B1: Value | C1: What it does | D1: Where it came from
A2: Capital (₹) | B2: 5000 | C2: Account size. Used for return % and the account-wipe floor. | D2: You
A3: Leverage | B3: 10 | C3: 10x isolated. | D3: You
A4: Risk per trade (₹) | B4: 100 | C4: A stop-out should lose at most this (before fees). Position is sized to it, then floored to the exchange step. | D4: You (2% of capital)
A5: USD/INR | B5: 88 | C5: Converts the ₹ risk into BTC quantity. Notional ₹ = qty x entry x this. | D5: Assumed — set near the live rate
A6: Pair / timeframe | B6: B-BTC_USDT 15m | C6: CoinDCX futures candles. | D6: Your rule
A7: Sessions (IST) | B7: London 13:00–18:45, New York 19:00–01:15 | C7: First 15m candle of each session sets the high/low range. | D7: Your rule
A8: Entry deadline (IST) | B8: London 14:45, New York 20:45 | C8: No new entries after this. | D8: Your rule
A9: Trades per session | B9: 1 | C9: One trade per session. | D9: Your rule
A10: Entry | B10: Next candle open after the trigger candle closes (+ slippage) | C10: Never enters on the trigger candle itself. | D10: Your rule
A11: Breakout qualifies if | B11: Closes beyond the level, >=50% of the candle beyond it | C11: Close-strength test. | D11: Your rule (v5 condition 1)
A12: Stop buffer SA1 / SA4 | B12: 0.0015 | C12: Stop sits this far beyond the broken level. | D12: Your rule (v5 condition 3)
A13: Stop buffer SA2 | B13: 0.0045 | C13: Wider stop for the tap/rejection sub-agent. | D13: CHOSEN BY ME from a parameter sweep — not your number. Check.
A14: Partial exit | B14: 50% of the position at +0.5R | C14: Quantised to 0.001 BTC; skipped if it cannot be split into two valid orders. | D14: Your rule (v5 conditions 5)
A15: Trail | B15: 0.25R behind the best price, from +0.5R | C15: Intrabar. | D15: Your rule (v5 condition 6)
A16: Breakeven stop | B16: At +1.0R, stop to entry +0.16% | C16: Covers fees. | D16: +0.16% is yours (v5 condition 7); the +1.0R trigger is my setting. Check.
A17: Doji body / pin-wick multiple | B17: 10% / 2.0 | C17: How the engine recognises a doji or rejection wick. | D17: MY INTERPRETATION of your wording. Check.
A18: Tap tolerance | B18: 0.0006 | C18: How close counts as 'tapping' the line. | D18: MY INTERPRETATION ('very close'). Check.
A19: Clean-breakout touch tolerance | B19: 0.15 | C19: SA4: how far a candle may overlap the lines and still be 'clean'. | D19: MY INTERPRETATION. Check.
A20: Momentum window (SA4) | B20: 2 candles | C20: SA4 waits this many candles for a reversal before entering. | D20: MY INTERPRETATION. Check.
A21: Taker fee (per side) | B21: 0.00059 | C21: Charged on entry and on each exit leg. All exits modelled as market/stop orders. | D21: ASSUMED — never confirmed against your CoinDCX account. 0.059% would be 0.05% + 18% GST.
A22: Maker fee | B22: 0 | C22: Not used: nothing is modelled as a resting limit order. | D22: Assumed
A23: Slippage (per side) | B23: 0.0002 | C23: Applied to every fill price (entry and exit). It is INSIDE the gross figure in my notebook. | D23: ASSUMED
A24: Funding (per 8h) | B24: 0.0001 | C24: Charged on hold time. | D24: ASSUMED (typical BTC perpetual)
A25: Maintenance margin | B25: 0.005 | C25: Liquidation modelling only. | D25: Assumed
A26: Daily loss limit (₹) | B26: 500 | C26: Stops trading for the day. | D26: MY safety rule, not yours
A27: Consecutive-loss halt | B27: 4 losses -> skip 1 day | C27: Streak counted across days. | D27: MY safety rule, not yours
A28: Contract spec | B28: Step 0.001 BTC, min 0.001, min notional 60 USDT, tick 0.1 | C28: Read from CoinDCX itself. | D28: CoinDCX
A29: Data | B29: CoinDCX futures, 27,882 candles, 31 Dec 2025 18:00 IST -> 18 Oct 2026 04:15 IST | C29: 100% of expected candles, 0 gaps, 0 malformed. | D29: CoinDCX public API

Sheet Trades
A1: Date | B1: Day | C1: Session | D1: Sub-agent | E1: Side | F1: Entry time (IST) | G1: Entry price (after slippage) | H1: Stop price | I1: Exit time (IST) | J1: Exit price (after slippage) | K1: Exit reason | L1: Qty (BTC) | M1: Notional ₹ | N1: Hours held | O1: Gross ₹ as run (after slippage) | P1: NET ₹ as run | Q1: Fees ₹ as run | R1: Funding ₹ as run (derived) | S1: Gross ₹ before slippage | T1: Gross ₹ with YOUR slippage | U1: Fees ₹ with YOUR fee | V1: Funding ₹ with YOUR rate | W1: NET ₹ with YOUR values | X1: Month
A2: 2025-12-31 | B2: Wed | C2: New York | D2: SA1 | E2: LONG | F2: 46022.812 | G2: 88972.091 | H2: 88672.591 | I2: 46022.812 | J2: 89100.102 | K2: trailing_stop | L2: 0.003 | M2: =L2*G2*Settings!$B$5 -> 23488.632 | N2: =(I2-F2)*24 -> 0 | O2: 34.139313 | P2: 6.4227275 | Q2: =2*Calculator!$C$5*M2 -> 27.716586 | R2: =O2-P2-Q2 -> 0 | S2: =O2+2*Calculator!$C$6*M2 -> 43.534766 | T2: =S2-2*Calculator!$B$6*M2 -> 34.139313 | U2: =2*Calculator!$B$5*M2 -> 27.716586 | V2: =R2*Calculator!$B$7/Calculator!$C$7 -> 0 | W2: =T2-U2-V2 -> 6.4227275 | X2: =LEFT(A2,7) -> 2025-12
A3: 2026-01-01 | B3: Thu | C3: London | D3: SA2 | E3: SHORT | F3: 46023.562 | G3: 87586.179 | H3: 88031.869 | I3: 46023.781 | J3: 87957.988 | K3: session_end | L3: 0.002 | M3: =L3*G3*Settings!$B$5 -> 15415.168 | N3: =(I3-F3)*24 -> 5.25 | O3: -65.438352 | P3: -84.63987 | Q3: =2*Calculator!$C$5*M3 -> 18.189898 | R3: =O3-P3-Q3 -> 1.0116204 | S3: =O3+2*Calculator!$C$6*M3 -> -59.272285 | T3: =S3-2*Calculator!$B$6*M3 -> -65.438352 | U3: =2*Calculator!$B$5*M3 -> 18.189898 | V3: =R3*Calculator!$B$7/Calculator!$C$7 -> 1.0116204 | W3: =T3-U3-V3 -> -84.63987 | X3: =LEFT(A3,7) -> 2026-01
A4: 2026-01-02 | B4: Fri | C4: London | D4: SA2 | E4: SHORT | F4: 46024.562 | G4: 88811.534 | H4: 89283.375 | I4: 46024.604 | J4: 89301.232 | K4: stop_loss | L4: 0.002 | M4: =L4*G4*Settings!$B$5 -> 15630.83 | N4: =(I4-F4)*24 -> 1 | O4: -86.186819 | P4: -104.82658 | Q4: =2*Calculator!$C$5*M4 -> 18.444379 | R4: =O4-P4-Q4 -> 0.19538538 | S4: =O4+2*Calculator!$C$6*M4 -> -79.934487 | T4: =S4-2*Calculator!$B$6*M4 -> -86.186819 | U4: =2*Calculator!$B$5*M4 -> 18.444379 | V4: =R4*Calculator!$B$7/Calculator!$C$7 -> 0.19538538 | W4: =T4-U4-V4 -> -104.82658 | X4: =LEFT(A4,7) -> 2026-01
A5: 2026-01-03 | B5: Sat | C5: London | D5: SA2 | E5: SHORT | F5: 46025.573 | G5: 89467.303 | H5: 89957.997 | I5: 46025.76 | J5: 89975.989 | K5: stop_loss | L5: 0.002 | M5: =L5*G5*Settings!$B$5 -> 15746.245 | N5: =(I5-F5)*24 -> 4.5 | O5: -89.528761 | P5: -108.99506 | Q5: =2*Calculator!$C$5*M5 -> 18.580569 | R5: =O5-P5-Q5 -> 0.8857263 | S5: =O5+2*Calculator!$C$6*M5 -> -83.230262 | T5: =S5-2*Calculator!$B$6*M5 -> -89.528761 | U5: =2*Calculator!$B$5*M5 -> 18.580569 | V5: =R5*Calculator!$B$7/Calculator!$C$7 -> 0.8857263 | W5: =T5-U5-V5 -> -108.99506 | X5: =LEFT(A5,7) -> 2026-01
A6: 2026-01-04 | B6: Sun | C6: New York | D6: SA4 | E6: LONG | F6: 46026.844 | G6: 91188.234 | H6: 91094.154 | I6: 46026.844 | J6: 91315.868 | K6: breakeven_stop | L6: 0.006 | M6: =L6*G6*Settings!$B$5 -> 48147.388 | N6: =(I6-F6)*24 -> 0 | O6: 41.296871 | P6: -15.517046 | Q6: =2*Calculator!$C$5*M6 -> 56.813917 | R6: =O6-P6-Q6 -> 0 | S6: =O6+2*Calculator!$C$6*M6 -> 60.555826 | T6: =S6-2*Calculator!$B$6*M6 -> 41.296871 | U6: =2*Calculator!$B$5*M6 -> 56.813917 | V6: =R6*Calculator!$B$7/Calculator!$C$7 -> 0 | W6: =T6-U6-V6 -> -15.517046 | X6: =LEFT(A6,7) -> 2026-01
A7: 2026-01-06 | B7: Tue | C7: London | D7: SA2 | E7: LONG | F7: 46028.562 | G7: 93226.041 | H7: 92741.278 | I7: 46028.604 | J7: 93349.935 | K7: trailing_stop | L7: 0.002 | M7: =L7*G7*Settings!$B$5 -> 16407.783 | N7: =(I7-F7)*24 -> 1 | O7: 30.58722 | P7: 11.020938 | Q7: =2*Calculator!$C$5*M7 -> 19.361184 | R7: =O7-P7-Q7 -> 0.20509729 | S7: =O7+2*Calculator!$C$6*M7 -> 37.150333 | T7: =S7-2*Calculator!$B$6*M7 -> 30.58722 | U7: =2*Calculator!$B$5*M7 -> 19.361184 | V7: =R7*Calculator!$B$7/Calculator!$C$7 -> 0.20509729 | W7: =T7-U7-V7 -> 11.020938 | X7: =LEFT(A7,7) -> 2026-01
A8: 2026-01-06 | B8: Tue | C8: New York | D8: SA2 | E8: LONG | F8: 46028.812 | G8: 93696.736 | H8: 93198.61 | I8: 46028.823 | J8: 94006.664 | K8: trailing_stop | L8: 0.002 | M8: =L8*G8*Settings!$B$5 -> 16490.625 | N8: =(I8-F8)*24 -> 0.25 | O8: 47.537726 | P8: 28.053022 | Q8: =2*Calculator!$C$5*M8 -> 19.458938 | R8: =O8-P8-Q8 -> 0.025766602 | S8: =O8+2*Calculator!$C$6*M8 -> 54.133976 | T8: =S8-2*Calculator!$B$6*M8 -> 47.537726 | U8: =2*Calculator!$B$5*M8 -> 19.458938 | V8: =R8*Calculator!$B$7/Calculator!$C$7 -> 0.025766602 | W8: =T8-U8-V8 -> 28.053022 | X8: =LEFT(A8,7) -> 2026-01
A9: 2026-01-09 | B9: Fri | C9: London | D9: SA1 | E9: SHORT | F9: 46031.562 | G9: 90693.958 | H9: 91002.9 | I9: 46031.562 | J9: 90511.834 | K9: trailing_stop | L9: 0.003 | M9: =L9*G9*Settings!$B$5 -> 23943.205 | N9: =(I9-F9)*24 -> 0 | O9: 44.05366 | P9: 15.800678 | Q9: =2*Calculator!$C$5*M9 -> 28.252982 | R9: =O9-P9-Q9 -> 0 | S9: =O9+2*Calculator!$C$6*M9 -> 53.630942 | T9: =S9-2*Calculator!$B$6*M9 -> 44.05366 | U9: =2*Calculator!$B$5*M9 -> 28.252982 | V9: =R9*Calculator!$B$7/Calculator!$C$7 -> 0 | W9: =T9-U9-V9 -> 15.800678 | X9: =LEFT(A9,7) -> 2026-01
A10: 2026-01-11 | B10: Sun | C10: New York | D10: SA2 | E10: LONG | F10: 46033.812 | G10: 90830.062 | H10: 90371.49 | I10: 46033.854 | J10: 91010.251 | K10: trailing_stop | L10: 0.002 | M10: =L10*G10*Settings!$B$5 -> 15986.091 | N10: =(I10-F10)*24 -> 1 | O10: 34.431158 | P10: 15.392722 | Q10: =2*Calculator!$C$5*M10 -> 18.863587 | R10: =O10-P10-Q10 -> 0.17484787 | S10: =O10+2*Calculator!$C$6*M10 -> 40.825594 | T10: =S10-2*Calculator!$B$6*M10 -> 34.431158 | U10: =2*Calculator!$B$5*M10 -> 18.863587 | V10: =R10*Calculator!$B$7/Calculator!$C$7 -> 0.17484787 | W10: =T10-U10-V10 -> 15.392722 | X10: =LEFT(A10,7) -> 2026-01
A11: 2026-01-12 | B11: Mon | C11: London | D11: SA1 | E11: SHORT | F11: 46034.562 | G11: 91350.926 | H11: 91624.831 | I11: 46034.583 | J11: 90537.58 | K11: trailing_stop | L11: 0.004 | M11: =L11*G11*Settings!$B$5 -> 32155.526 | N11: =(I11-F11)*24 -> 0.5 | O11: 164.04182 | P11: 125.89732 | Q11: =2*Calculator!$C$5*M11 -> 37.943521 | R11: =O11-P11-Q11 -> 0.20097204 | S11: =O11+2*Calculator!$C$6*M11 -> 176.90403 | T11: =S11-2*Calculator!$B$6*M11 -> 164.04182 | U11: =2*Calculator!$B$5*M11 -> 37.943521 | V11: =R11*Calculator!$B$7/Calculator!$C$7 -> 0.20097204 | W11: =T11-U11-V11 -> 125.89732 | X11: =LEFT(A11,7) -> 2026-01
A12: 2026-01-12 | B12: Mon | C12: New York | D12: SA2 | E12: LONG | F12: 46034.812 | G12: 90614.819 | H12: 90148.398 | I12: 46034.823 | J12: 90130.369 | K12: stop_loss | L12: 0.002 | M12: =L12*G12*Settings!$B$5 -> 15948.208 | N12: =(I12-F12)*24 -> 0.25 | O12: -85.2633 | P12: -104.13202 | Q12: =2*Calculator!$C$5*M12 -> 18.818886 | R12: =O12-P12-Q12 -> 0.049838151 | S12: =O12+2*Calculator!$C$6*M12 -> -78.884017 | T12: =S12-2*Calculator!$B$6*M12 -> -85.2633 | U12: =2*Calculator!$B$5*M12 -> 18.818886 | V12: =R12*Calculator!$B$7/Calculator!$C$7 -> 0.049838151 | W12: =T12-U12-V12 -> -104.13202 | X12: =LEFT(A12,7) -> 2026-01
A13: 2026-01-13 | B13: Tue | C13: London | D13: SA2 | E13: LONG | F13: 46035.562 | G13: 91926.382 | H13: 91485.156 | I13: 46035.604 | J13: 92105.969 | K13: trailing_stop | L13: 0.002 | M13: =L13*G13*Settings!$B$5 -> 16179.043 | N13: =(I13-F13)*24 -> 1 | O13: 33.595809 | P13: 14.35286 | Q13: =2*Calculator!$C$5*M13 -> 19.091271 | R13: =O13-P13-Q13 -> 0.15167853 | S13: =O13+2*Calculator!$C$6*M13 -> 40.067427 | T13: =S13-2*Calculator!$B$6*M13 -> 33.595809 | U13: =2*Calculator!$B$5*M13 -> 19.091271 | V13: =R13*Calculator!$B$7/Calculator!$C$7 -> 0.15167853 | W13: =T13-U13-V13 -> 14.35286 | X13: =LEFT(A13,7) -> 2026-01
... A302: 2026-10-16 | B302: Fri | C302: London | D302: SA1 | E302: LONG | F302: 46311.562 | G302: 82276.852 | H302: 82073.205 | I302: 46311.625 | J302: 82056.791 | K302: stop_loss | L302: 0.005 | M302: =L302*G302*Settings!$B$5 -> 36201.815 | N302: =(I302-F302)*24 -> 1.5 | O302: -96.827047 | P302: -140.22397 | Q302: =2*Calculator!$C$5*M302 -> 42.718142 | R302: =O302-P302-Q302 -> 0.67878403 | S302: =O302+2*Calculator!$C$6*M302 -> -82.346321 | T302: =S302-2*Calculator!$B$6*M302 -> -96.827047 | U302: =2*Calculator!$B$5*M302 -> 42.718142 | V302: =R302*Calculator!$B$7/Calculator!$C$7 -> 0.67878403 | W302: =T302-U302-V302 -> -140.22397 | X302: =LEFT(A302,7) -> 2026-10

Sheet Signals
A1: date | B1: session | C1: range_high | D1: range_low | E1: range_pct | F1: sub_agent | G1: setup | H1: direction | I1: breakout | J1: rejection | K1: momentum_shift | L1: tp | M1: action | N1: reason | O1: entry | P1: sl | Q1: pnl_inr | R1: exit_reason
A2: 2025-12-31 | B2: New York | C2: 88805.8 | D2: 88705.3 | E2: 0.001132965 | F2: SA1 | G2: Second-candle clear breakout | H2: LONG | I2: =TRUE() -> TRUE | J2: =FALSE() -> FALSE | K2: =FALSE() -> FALSE | L2: trail/partial | M2: ENTER | N2: second candle closed above the high (strength 51%) | O2: 88972.09 | P2: 88672.59 | Q2: 6.42 | R2: trailing_stop
A3: 2026-01-01 | B3: London | C3: 87637.5 | D3: 87572.7 | E3: 0.00073995663 | F3: SA2 | G3: Line tap / rejection at the HIGH | H3: SHORT | I3: =FALSE() -> FALSE | J3: =TRUE() -> TRUE | K3: =FALSE() -> FALSE | L3: trail/partial | M3: ENTER | N3: 1 tap(s) of the high, rejected by doji_at_high | O3: 87586.18 | P3: 88031.87 | Q3: -84.64 | R3: session_end
A4: 2026-01-01 | B4: New York | C4: 87950 | D4: 87901.1 | E4: 0.00055630703 | F4: - | G4: no setup | H4: - | I4: =FALSE() -> FALSE | J4: =FALSE() -> FALSE | K4: =FALSE() -> FALSE | L4: trail/partial | M4: AVOID | N4: No sub-agent condition met this session
A5: 2026-01-02 | B5: London | C5: 88883.4 | D5: 88800.9 | E5: 0.00092904464 | F5: SA2 | G5: Line tap / rejection at the HIGH | H5: SHORT | I5: =FALSE() -> FALSE | J5: =TRUE() -> TRUE | K5: =FALSE() -> FALSE | L5: trail/partial | M5: ENTER | N5: 1 tap(s) of the high, rejected by doji_at_high | O5: 88811.53 | P5: 89283.38 | Q5: -104.83 | R5: stop_loss
A6: 2026-01-02 | B6: New York | C6: 89539.6 | D6: 89355.7 | E6: 0.0020580668 | F6: - | G6: no setup | H6: - | I6: =FALSE() -> FALSE | J6: =FALSE() -> FALSE | K6: =FALSE() -> FALSE | L6: trail/partial | M6: AVOID | N6: No sub-agent condition met this session
A7: 2026-01-03 | B7: London | C7: 89555 | D7: 89261.2 | E7: 0.0032914637 | F7: SA2 | G7: Line tap / rejection at the HIGH | H7: SHORT | I7: =FALSE() -> FALSE | J7: =TRUE() -> TRUE | K7: =FALSE() -> FALSE | L7: trail/partial | M7: ENTER | N7: 2 tap(s) of the high, rejected by upper_wick_rejection | O7: 89467.3 | P7: 89958 | Q7: -109 | R7: stop_loss
A8: 2026-01-03 | B8: New York | C8: 90007.2 | D8: 89902.4 | E8: 0.0011657086 | F8: - | G8: no setup | H8: - | I8: =FALSE() -> FALSE | J8: =FALSE() -> FALSE | K8: =FALSE() -> FALSE | L8: trail/partial | M8: AVOID | N8: No sub-agent condition met this session
A9: 2026-01-04 | B9: London | C9: 91463.1 | D9: 91264 | E9: 0.0021815831 | F9: - | G9: no setup | H9: - | I9: =FALSE() -> FALSE | J9: =FALSE() -> FALSE | K9: =FALSE() -> FALSE | L9: trail/partial | M9: AVOID | N9: No sub-agent condition met this session
A10: 2026-01-04 | B10: New York | C10: 91231 | D10: 91116.2 | E10: 0.0012599296 | F10: SA4 | G10: Clean breakout, candle not touching the marked lines | H10: LONG | I10: =TRUE() -> TRUE | J10: =FALSE() -> FALSE | K10: =FALSE() -> FALSE | L10: trail/partial | M10: ENTER | N10: no reversal candle in the momentum window | O10: 91188.23 | P10: 91094.15 | Q10: -15.52 | R10: breakeven_stop
A11: 2026-01-05 | B11: London | C11: 92571.6 | D11: 92502.8 | E11: 0.00074376127 | F11: - | G11: no setup | H11: - | I11: =FALSE() -> FALSE | J11: =FALSE() -> FALSE | K11: =FALSE() -> FALSE | L11: trail/partial | M11: AVOID | N11: Halted after a losing streak
A12: 2026-01-05 | B12: New York | C12: 92755.6 | D12: 92496.9 | E12: 0.0027968505 | F12: - | G12: no setup | H12: - | I12: =FALSE() -> FALSE | J12: =FALSE() -> FALSE | K12: =FALSE() -> FALSE | L12: trail/partial | M12: AVOID | N12: Halted after a losing streak
A13: 2026-01-06 | B13: London | C13: 93379.6 | D13: 93160.5 | E13: 0.0023518551 | F13: SA2 | G13: Line tap / rejection at the LOW | H13: LONG | I13: =FALSE() -> FALSE | J13: =TRUE() -> TRUE | K13: =FALSE() -> FALSE | L13: trail/partial | M13: ENTER | N13: 1 tap(s) of the low, rejected by lower_wick_rejection | O13: 93226.04 | P13: 92741.28 | Q13: 11.02 | R13: trailing_stop
A14: 2026-01-06 | B14: New York | C14: 93724.6 | D14: 93619.9 | E14: 0.001118352 | F14: SA2 | G14: Line tap / rejection at the LOW | H14: LONG | I14: =FALSE() -> FALSE | J14: =TRUE() -> TRUE | K14: =FALSE() -> FALSE | L14: trail/partial | M14: ENTER | N14: 1 tap(s) of the low, rejected by lower_wick_rejection | O14: 93696.74 | P14: 93198.61 | Q14: 28.05 | R14: trailing_stop
A15: 2026-01-07 | B15: London | C15: 92862.4 | D15: 92735.5 | E15: 0.001368408 | F15: - | G15: no setup | H15: - | I15: =FALSE() -> FALSE | J15: =FALSE() -> FALSE | K15: =FALSE() -> FALSE | L15: trail/partial | M15: AVOID | N15: No sub-agent condition met this session
A16: 2026-01-07 | B16: New York | C16: 92217 | D16: 92017.6 | E16: 0.0021669768 | F16: - | G16: no setup | H16: - | I16: =FALSE() -> FALSE | J16: =FALSE() -> FALSE | K16: =FALSE() -> FALSE | L16: trail/partial | M16: AVOID | N16: No sub-agent condition met this session
A17: 2026-01-08 | B17: London | C17: 90429.2 | D17: 90165.6 | E17: 0.0029235096 | F17: - | G17: no setup | H17: - | I17: =FALSE() -> FALSE | J17: =FALSE() -> FALSE | K17: =FALSE() -> FALSE | L17: trail/partial | M17: AVOID | N17: No sub-agent condition met this session
A18: 2026-01-08 | B18: New York | C18: 90067.8 | D18: 89845.7 | E18: 0.0024720159 | F18: - | G18: no setup | H18: - | I18: =FALSE() -> FALSE | J18: =FALSE() -> FALSE | K18: =FALSE() -> FALSE | L18: trail/partial | M18: AVOID | N18: No sub-agent condition met this session
A19: 2026-01-09 | B19: London | C19: 90993.7 | D19: 90866.6 | E19: 0.0013987538 | F19: SA1 | G19: Second-candle clear breakout | H19: SHORT | I19: =TRUE() -> TRUE | J19: =FALSE() -> FALSE | K19: =FALSE() -> FALSE | L19: trail/partial | M19: ENTER | N19: second candle closed below the low (strength 65%) | O19: 90693.96 | P19: 91002.9 | Q19: 15.8 | R19: trailing_stop
A20: 2026-01-09 | B20: New York | C20: 91000 | D20: 90346.9 | E20: 0.0072288036 | F20: - | G20: no setup | H20: - | I20: =FALSE() -> FALSE | J20: =FALSE() -> FALSE | K20: =FALSE() -> FALSE | L20: trail/partial | M20: AVOID | N20: No sub-agent condition met this session
A21: 2026-01-10 | B21: London | C21: 90650.4 | D21: 90562.3 | E21: 0.00097281098 | F21: - | G21: no setup | H21: - | I21: =FALSE() -> FALSE | J21: =FALSE() -> FALSE | K21: =FALSE() -> FALSE | L21: trail/partial | M21: AVOID | N21: No sub-agent condition met this session
A22: 2026-01-10 | B22: New York | C22: 90694.3 | D22: 90663.8 | E22: 0.0003364077 | F22: - | G22: no setup | H22: - | I22: =FALSE() -> FALSE | J22: =FALSE() -> FALSE | K22: =FALSE() -> FALSE | L22: trail/partial | M22: AVOID | N22: No sub-agent condition met this session
A23: 2026-01-11 | B23: London | C23: 90698.9 | D23: 90654.7 | E23: 0.00048756435 | F23: - | G23: no setup | H23: - | I23: =FALSE() -> FALSE | J23: =FALSE() -> FALSE | K23: =FALSE() -> FALSE | L23: trail/partial | M23: AVOID | N23: No sub-agent condition met this session
A24: 2026-01-11 | B24: New York | C24: 90841.6 | D24: 90780 | E24: 0.00067856356 | F24: SA2 | G24: Line tap / rejection at the LOW | H24: LONG | I24: =FALSE() -> FALSE | J24: =TRUE() -> TRUE | K24: =FALSE() -> FALSE | L24: trail/partial | M24: ENTER | N24: 1 tap(s) of the low, rejected by bullish_close_at_low | O24: 90830.06 | P24: 90371.49 | Q24: 15.39 | R24: trailing_stop
A25: 2026-01-12 | B25: London | C25: 91858.5 | D25: 91487.6 | E25: 0.0040541013 | F25: SA1 | G25: Second-candle clear breakout | H25: SHORT | I25: =TRUE() -> TRUE | J25: =FALSE() -> FALSE | K25: =FALSE() -> FALSE | L25: trail/partial | M25: ENTER | N25: second candle closed below the low (strength 61%) | O25: 91350.93 | P25: 91624.83 | Q25: 125.9 | R25: trailing_stop
A26: 2026-01-12 | B26: New York | C26: 90753.5 | D26: 90555.9 | E26: 0.0021820776 | F26: SA2 | G26: Line tap / rejection at the LOW | H26: LONG | I26: =FALSE() -> FALSE | J26: =TRUE() -> TRUE | K26: =FALSE() -> FALSE | L26: trail/partial | M26: ENTER | N26: 1 tap(s) of the low, rejected by lower_wick_rejection | O26: 90614.82 | P26: 90148.4 | Q26: -104.13 | R26: stop_loss
A27: 2026-01-13 | B27: London | C27: 92000 | D27: 91898.7 | E27: 0.0011023007 | F27: SA2 | G27: Line tap / rejection at the LOW | H27: LONG | I27: =FALSE() -> FALSE | J27: =TRUE() -> TRUE | K27: =FALSE() -> FALSE | L27: trail/partial | M27: ENTER | N27: 1 tap(s) of the low, rejected by doji_at_low | O27: 91926.38 | P27: 91485.16 | Q27: 14.35 | R27: trailing_stop
A28: 2026-01-13 | B28: New York | C28: 92555.1 | D28: 91836.3 | E28: 0.0078269704 | F28: SA2 | G28: Line tap / rejection at the LOW | H28: LONG | I28: =FALSE() -> FALSE | J28: =TRUE() -> TRUE | K28: =FALSE() -> FALSE | L28: trail/partial | M28: ENTER | N28: 1 tap(s) of the low, rejected by lower_wick_rejection | O28: 91946.99 | P28: 91423.04 | Q28: 71.96 | R28: trailing_stop
A29: 2026-01-14 | B29: London | C29: 95009.7 | D29: 94812 | E29: 0.0020851791 | F29: SA1 | G29: Second-candle clear breakout | H29: LONG | I29: =TRUE() -> TRUE | J29: =FALSE() -> FALSE | K29: =FALSE() -> FALSE | L29: trail/partial | M29: ENTER | N29: second candle closed above the high (strength 63%, fully clear) | O29: 95185.63 | P29: 94867.19 | Q29: -118.97 | R29: stop_loss
A30: 2026-01-14 | B30: New York | C30: 95169.8 | D30: 95008 | E30: 0.0017030145 | F30: - | G30: no setup | H30: - | I30: =FALSE() -> FALSE | J30: =FALSE() -> FALSE | K30: =FALSE() -> FALSE | L30: trail/partial | M30: AVOID | N30: No sub-agent condition met this session
A31: 2026-01-15 | B31: London | C31: 96744.2 | D31: 96408 | E31: 0.0034872625 | F31: - | G31: no setup | H31: - | I31: =FALSE() -> FALSE | J31: =FALSE() -> FALSE | K31: =FALSE() -> FALSE | L31: trail/partial | M31: AVOID | N31: No sub-agent condition met this session
A32: 2026-01-15 | B32: New York | C32: 96896.2 | D32: 96562.5 | E32: 0.0034557929 | F32: SA2 | G32: Line tap / rejection at the HIGH | H32: SHORT | I32: =FALSE() -> FALSE | J32: =TRUE() -> TRUE | K32: =FALSE() -> FALSE | L32: trail/partial | M32: ENTER | N32: 1 tap(s) of the high, rejected by upper_wick_rejection | O32: 96781.54 | P32: 97332.23 | Q32: 77.9 | R32: trailing_stop
A33: 2026-01-16 | B33: London | C33: 95548 | D33: 95432.6 | E33: 0.0012092304 | F33: - | G33: no setup | H33: - | I33: =FALSE() -> FALSE | J33: =FALSE() -> FALSE | K33: =FALSE() -> FALSE | L33: trail/partial | M33: AVOID | N33: No sub-agent condition met this session
A34: 2026-01-16 | B34: New York | C34: 95537.9 | D34: 95238 | E34: 0.0031489531 | F34: SA2 | G34: Line tap / rejection at the HIGH | H34: SHORT | I34: =FALSE() -> FALSE | J34: =TRUE() -> TRUE | K34: =FALSE() -> FALSE | L34: trail/partial | M34: ENTER | N34: 1 tap(s) of the high, rejected by doji_at_high | O34: 95385.42 | P34: 95967.82 | Q34: 8.98 | R34: trailing_stop
A35: 2026-01-17 | B35: London | C35: 95147.8 | D35: 95102.2 | E35: 0.00047948418 | F35: SA1 | G35: Second-candle clear breakout | H35: SHORT | I35: =TRUE() -> TRUE | J35: =FALSE() -> FALSE | K35: =FALSE() -> FALSE | L35: trail/partial | M35: ENTER | N35: second candle closed below the low (strength 39%, fully clear) | O35: 95042.09 | P35: 95244.85 | Q35: -147.73 | R35: stop_loss
A36: 2026-01-17 | B36: New York | C36: 95396.8 | D36: 95276.1 | E36: 0.0012668445 | F36: - | G36: no setup | H36: - | I36: =FALSE() -> FALSE | J36: =FALSE() -> FALSE | K36: =FALSE() -> FALSE | L36: trail/partial | M36: AVOID | N36: No sub-agent condition met this session
A37: 2026-01-18 | B37: London | C37: 95073 | D37: 94980 | E37: 0.00097915351 | F37: SA2 | G37: Line tap / rejection at the HIGH | H37: SHORT | I37: =FALSE() -> FALSE | J37: =TRUE() -> TRUE | K37: =FALSE() -> FALSE | L37: trail/partial | M37: ENTER | N37: 1 tap(s) of the high, rejected by upper_wick_rejection | O37: 94970.9 | P37: 95500.83 | Q37: -29.29 | R37: session_end
A38: 2026-01-18 | B38: New York | C38: 95158 | D38: 94903.5 | E38: 0.0026816714 | F38: SA2 | G38: Line tap / rejection at the HIGH | H38: SHORT | I38: =FALSE() -> FALSE | J38: =TRUE() -> TRUE | K38: =FALSE() -> FALSE | L38: trail/partial | M38: ENTER | N38: 1 tap(s) of the high, rejected by upper_wick_rejection | O38: 95085.98 | P38: 95586.21 | Q38: -72.48 | R38: session_end
A39: 2026-01-19 | B39: London | C39: 92665.1 | D39: 92527.3 | E39: 0.0014892902 | F39: SA1 | G39: Second-candle clear breakout | H39: LONG | I39: =TRUE() -> TRUE | J39: =FALSE() -> FALSE | K39: =FALSE() -> FALSE | L39: trail/partial | M39: ENTER | N39: second candle closed above the high (strength 60%) | O39: 92806.36 | P39: 92526.1 | Q39: 35.04 | R39: trailing_stop
A40: 2026-01-19 | B40: New York | C40: 93117.1 | D40: 92906.2 | E40: 0.0022700315 | F40: - | G40: no setup | H40: - | I40: =FALSE() -> FALSE | J40: =FALSE() -> FALSE | K40: =FALSE() -> FALSE | L40: trail/partial | M40: AVOID | N40: No sub-agent condition met this session
...

Sheet Sensitivity
A1: Exact re-runs of the engine (notebook cell 7). Each row changes ONE setting; fee rows also change which trades occur.
A3: Variant | B3: trades | C3: win | D3: gross_inr | E3: net_inr | F3: cost_inr | G3: PF | H3: exp_inr | I3: avg_R | J3: avg_risk_inr | K3: cost_in_R | L3: maxDD | M3: t_gross | N3: t_net
A4: FINAL (as run above) | B4: 301 | C4: 61.5% | D4: 1239 | E4: -4805 | F4: 6044 | G4: 0.53 | H4: -16 | I4: 0.102 | J4: 82 | K4: 0.32 | L4: -4811 | M4: 1.08 | N4: -4.17
A5: SA2 stop buffer 0.15% | B5: 289 | C5: 45.7% | D5: 1741 | E5: -8859 | F5: 10600 | G5: 0.34 | H5: -30.7 | I5: 0.181 | J5: 88 | K5: 0.55 | L5: -8865 | M5: 1.31 | N5: -6.5
A6: SA2 stop buffer 0.30% | B6: 301 | C6: 60.5% | D6: 402 | E6: -7154 | F6: 7556 | G6: 0.4 | H6: -23.8 | I6: 0.078 | J6: 85 | K6: 0.39 | L6: -7161 | M6: 0.34 | N6: -5.96
A7: SA2 stop buffer 0.60% | B7: 305 | C7: 58.4% | D7: 643 | E7: -4551 | F7: 5194 | G7: 0.54 | H7: -14.9 | I7: 0.071 | J7: 78 | K7: 0.28 | L7: -4758 | M7: 0.59 | N7: -4.13
A8: SA4 momentum window 1 | B8: 301 | C8: 61.5% | D8: 1181 | E8: -4870 | F8: 6052 | G8: 0.53 | H8: -16.2 | I8: 0.098 | J8: 82 | K8: 0.32 | L8: -4876 | M8: 1.03 | N8: -4.22
A9: SA4 momentum window 3 | B9: 301 | C9: 61.8% | D9: 1112 | E9: -4901 | F9: 6013 | G9: 0.53 | H9: -16.3 | I9: 0.092 | J9: 82 | K9: 0.32 | L9: -4907 | M9: 0.97 | N9: -4.24
A10: circuit breakers OFF | B10: 314 | C10: 60.5% | D10: 684 | E10: -5649 | F10: 6333 | G10: 0.5 | H10: -18 | I10: 0.076 | J10: 82 | K10: 0.32 | L10: -5683 | M10: 0.58 | N10: -4.75
A11: taker fee 0.040% | B11: 304 | C11: 63.8% | D11: 958 | E11: -3216 | F11: 4174 | G11: 0.67 | H11: -10.6 | I11: 0.09 | J11: 82 | K11: 0.24 | L11: -3231 | M11: 0.83 | N11: -2.77
A12: taker fee 0.020% | B12: 304 | C12: 64.1% | D12: 958 | E12: -1163 | F12: 2121 | G12: 0.87 | H12: -3.8 | I12: 0.09 | J12: 82 | K12: 0.16 | L12: -1230 | M12: 0.83 | N12: -1
